import React from 'react';

interface ErrorBoundaryState {
  hasError: boolean;
  error?: Error;
}

interface ErrorBoundaryProps {
  children: React.ReactNode;
  fallback?: React.ComponentType<{ error?: Error; retry: () => void }>;
}

export class ErrorBoundary extends React.Component<ErrorBoundaryProps, ErrorBoundaryState> {
  constructor(props: ErrorBoundaryProps) {
    super(props);
    this.state = { hasError: false };
  }

  static getDerivedStateFromError(error: Error): ErrorBoundaryState {
    return { hasError: true, error };
  }

  componentDidCatch(error: Error, errorInfo: React.ErrorInfo) {
    console.error('Error caught by boundary:', error, errorInfo);
  }

  render() {
    if (this.state.hasError) {
      const FallbackComponent = this.props.fallback || DefaultErrorFallback;
      return (
        <FallbackComponent 
          error={this.state.error} 
          retry={() => this.setState({ hasError: false, error: undefined })}
        />
      );
    }

    return this.props.children;
  }
}

function DefaultErrorFallback({ error, retry }: { error?: Error; retry: () => void }) {
  return (
    <div className="glass p-6 text-center">
      <h2 className="text-lg font-semibold text-red-400 mb-2">Something went wrong</h2>
      <p className="text-sm text-muted mb-4">
        {error?.message || "An unexpected error occurred"}
      </p>
      <button 
        onClick={retry}
        className="px-4 py-2 bg-primary text-white rounded-lg hover:bg-primary/90 transition-colors"
      >
        Try again
      </button>
    </div>
  );
}